Workbook

Sheet README
A1: Lumina Baby & Family Care Ltd — Commercial Finance — Pricing, Margin & Customer Profitability
A3: Project 2 | Commercial Finance flagship case study | V1
A5: Business problem
A6: Commercial Finance needs to identify which customers, channels and SKUs create profitable growth after discounts, COGS, freight and promotional spend. This project uses a SQL-first data pipeline and Excel reporting layer to answer that question.
A12: V1 build
A13: Data model | B13: Star schema: Fact Sales + Date/Product/Customer dimensions
A14: SQL | B14: SQLite database and reusable commercial-finance queries
A15: Customer profitability | B15: Net revenue, discount, GP, cost-to-serve, contribution
A16: Product profitability | B16: SKU, brand and category economics
A17: Channel analysis | B17: Route-to-market contribution and margin
A18: Monthly trend | B18: Revenue, discount, promo spend and margin
A19: Dashboard | B19: Commercial Finance KPI summary and charts
A20: Power BI prep | B20: CSV star schema + DAX measure library
A21: Data volume | B21: 2,000 synthetic transactions | 48 SKUs | 90 customers
A23: Portfolio integrity
A24: All company, customer, product and transaction data is synthetic. Present outputs as simulated/modelled findings, not realised employer results.
A40: V2 — Commercial Decision Layer
A41: V2 adds discount-leakage and repricing analysis, customer profitability quadrants, a pricing waterfall, promotion-effectiveness ROI proxies, customer-concentration / Pareto analysis, SKU rationalisation, Jan–Sep Price–Volume–Mix analysis and a quantified Commercial Finance action plan. The aim is to move from reporting revenue and margin to recommending pricing, customer, promotion and portfolio actions.
A50: V3 — Commercial Management Layer
A51: V3 adds a risk-adjusted customer repricing scenario model, an accountable customer action register, formula-driven Commercial Finance commentary, an executive management pack and a Power BI build specification. The repricing model explicitly balances discount recovery against volume-retention risk so that modelled upside is presented as a planning scenario rather than a guaranteed saving.
A60: Final Portfolio Release
A61: Final release prepared for CV, LinkedIn and interview use. The release package includes the final workbook, SQLite database, SQL queries, source CSVs, recruiter-facing screenshots, CV bullets, LinkedIn launch copy and interview explanations. Power BI is described only as a build specification because no PBIX file is included. All pricing opportunities are modelled scenarios, not realised savings.

Sheet Assumptions
A1: Commercial Assumptions
A3: Channel | B3: Typical Discount Range | C3: Freight % Net Revenue | D3: Source
A4: Grocery | B4: 9% – 16% | C4: 0.018 | D4: Synthetic assumption
A5: Pharmacy | B5: 7% – 13% | C5: 0.021 | D5: Synthetic assumption
A6: Online Marketplace | B6: 10% – 18% | C6: 0.026 | D6: Synthetic assumption
A7: DTC | B7: 2% – 8% | C7: 0.045 | D7: Synthetic assumption
A8: Wholesale | B8: 13% – 21% | C8: 0.015 | D8: Synthetic assumption
A9: Baby Specialist | B9: 6% – 12% | C9: 0.023 | D9: Synthetic assumption
A12: Portfolio Assumption | B12: Value
A13: 2026 price inflation | B13: 0.035
A14: 2026 unit-cost inflation | B14: 0.045
A15: Strategic discount premium | B15: 0.025
A16: Promotional discount increment | B16: 0.035
A17: Transaction lines | B17: 2000
A21: V2 Pricing Governance Assumptions
A22: Channel | B22: Target Base Discount | C22: Source
A23: Grocery | B23: 0.12 | C23: Synthetic pricing-policy assumption
A24: Pharmacy | B24: 0.1 | C24: Synthetic pricing-policy assumption
A25: Online Marketplace | B25: 0.14 | C25: Synthetic pricing-policy assumption
A26: DTC | B26: 0.05 | C26: Synthetic pricing-policy assumption
A27: Wholesale | B27: 0.16 | C27: Synthetic pricing-policy assumption
A28: Baby Specialist | B28: 0.09 | C28: Synthetic pricing-policy assumption
A30: V2 Customer / Promotion Policy
A31: Strategic tier premium | B31: 0.02
A32: Core tier premium | B32: 0.01
A33: Long-tail tier premium | B33: 0
A34: Promo-policy increment × promo sales share | B34: 0.02
A35: Potential leakage recapture factor | B35: 0.7

Sheet Data Model
A1: Power BI / SQL Star Schema
A3: Model relationships
A4: Table | B4: Primary Key | C4: Relationship | D4: Fact Key | E4: Grain | F4: Rows | G4: Purpose | H4: Source
A5: Dim Date | B5: Date | C5: 1 → many | D5: Fact Sales.Date | E5: 1 row per calendar day | F5: 638 | G5: Time intelligence | H5: Synthetic
A6: Dim Product | B6: Product_ID | C6: 1 → many | D6: Fact Sales.Product_ID | E6: 1 row per SKU | F6: 48 | G6: Product hierarchy | H6: Synthetic
A7: Dim Customer | B7: Customer_ID | C7: 1 → many | D7: Fact Sales.Customer_ID | E7: 1 row per customer | F7: 90 | G7: Customer/channel hierarchy | H7: Synthetic
A8: Fact Sales | B8: Transaction_ID | C8: many side | D8: — | E8: 1 transaction line | F8: 2000 | G8: Commercial economics | H8: Synthetic ERP/CRM extract

Sheet Dim Product
A1: Product Dimension
A3: Product_ID | B3: Brand | C3: Category | D3: SKU_Name | E3: Pack_Size | F3: Base_List_Price (£) | G3: Standard_Unit_Cost (£) | H3: Launch_Status | I3: Source
A4: P001 | B4: Nurtura | C4: Diapers | D4: Nurtura Diapers 24 pack | E4: 24 pack | F4: 10.5 | G4: 5.55 | H4: Core | I4: Synthetic portfolio master data
A5: P002 | B5: Nurtura | C5: Diapers | D5: Nurtura Diapers 40 pack | E5: 40 pack | F5: 16.28 | G5: 8.58 | H5: Core | I5: Synthetic portfolio master data
A6: P003 | B6: Nurtura | C6: Wipes | D6: Nurtura Wipes 4 pack | E6: 4 pack | F6: 5.2 | G6: 2.74 | H6: Core | I6: Synthetic portfolio master data
A7: P004 | B7: Nurtura | C7: Wipes | D7: Nurtura Wipes 8 pack | E7: 8 pack | F7: 8.06 | G7: 4.06 | H7: Core | I7: Synthetic portfolio master data
A8: P005 | B8: Nurtura | C8: Baby Bath | D8: Nurtura Baby Bath 250ml | E8: 250ml | F8: 4.8 | G8: 2.29 | H8: Core | I8: Synthetic portfolio master data
A9: P006 | B9: Nurtura | C9: Baby Bath | D9: Nurtura Baby Bath 500ml | E9: 500ml | F9: 7.44 | G9: 3.6 | H9: Core | I9: Synthetic portfolio master data
A10: P007 | B10: Nurtura | C10: Skincare | D10: Nurtura Skincare 100ml | E10: 100ml | F10: 6.4 | G10: 2.99 | H10: Growth | I10: Synthetic portfolio master data
A11: P008 | B11: Nurtura | C11: Skincare | D11: Nurtura Skincare 200ml | E11: 200ml | F11: 9.92 | G11: 4.57 | H11: Core | I11: Synthetic portfolio master data
A12: P009 | B12: Nurtura | C12: Feeding | D12: Nurtura Feeding 2 pack | E12: 2 pack | F12: 8.2 | G12: 4.03 | H12: Core | I12: Synthetic portfolio master data
A13: P010 | B13: Nurtura | C13: Feeding | D13: Nurtura Feeding 4 pack | E13: 4 pack | F13: 8.2 | G13: 4.14 | H13: Core | I13: Synthetic portfolio master data
A14: P011 | B14: Nurtura | C14: Nursery | D14: Nurtura Nursery Single | E14: Single | F14: 14.5 | G14: 8.03 | H14: Core | I14: Synthetic portfolio master data
A15: P012 | B15: Nurtura | C15: Nursery | D15: Nurtura Nursery Twin pack | E15: Twin pack | F15: 22.48 | G15: 12.47 | H15: Core | I15: Synthetic portfolio master data
... A51: P048 | B51: TinySteps | C51: Nursery | D51: TinySteps Nursery Twin pack | E51: Twin pack | F51: 20.23 | G51: 11.65 | H51: Core | I51: Synthetic portfolio master data

Sheet Dim Customer
A1: Customer Dimension
A3: Customer_ID | B3: Customer_Name | C3: Channel | D3: Region | E3: Tier | F3: Payment_Terms_Days | G3: Account_Status | H3: Source
A4: C001 | B4: Northgate Grocers 01 | C4: Grocery | D4: North | E4: Strategic | F4: 45 | G4: Active | H4: Synthetic portfolio master data
A5: C002 | B5: Northgate Grocers 02 | C5: Grocery | D5: Wales | E5: Strategic | F5: 45 | G5: Active | H5: Synthetic portfolio master data
A6: C003 | B6: Northgate Grocers 03 | C6: Grocery | D6: London & South East | E6: Strategic | F6: 45 | G6: Active | H6: Synthetic portfolio master data
A7: C004 | B7: Northgate Grocers 04 | C7: Grocery | D7: North | E7: Core | F7: 30 | G7: Active | H7: Synthetic portfolio master data
A8: C005 | B8: Northgate Grocers 05 | C8: Grocery | D8: Wales | E8: Core | F8: 30 | G8: Active | H8: Synthetic portfolio master data
A9: C006 | B9: Northgate Grocers 06 | C9: Grocery | D9: London & South East | E9: Core | F9: 30 | G9: Active | H9: Synthetic portfolio master data
A10: C007 | B10: Northgate Grocers 07 | C10: Grocery | D10: North | E10: Core | F10: 30 | G10: Active | H10: Synthetic portfolio master data
A11: C008 | B11: Northgate Grocers 08 | C11: Grocery | D11: Wales | E11: Core | F11: 30 | G11: Active | H11: Synthetic portfolio master data
A12: C009 | B12: Northgate Grocers 09 | C12: Grocery | D12: London & South East | E12: Core | F12: 30 | G12: Active | H12: Synthetic portfolio master data
A13: C010 | B13: Northgate Grocers 10 | C13: Grocery | D13: North | E13: Long Tail | F13: 21 | G13: Active | H13: Synthetic portfolio master data
A14: C011 | B14: Northgate Grocers 11 | C14: Grocery | D14: Wales | E14: Long Tail | F14: 21 | G14: Active | H14: Synthetic portfolio master data
A15: C012 | B15: Northgate Grocers 12 | C15: Grocery | D15: London & South East | E15: Long Tail | F15: 21 | G15: Active | H15: Synthetic portfolio master data
... A93: C090 | B93: LittleNest Retail 15 | C93: Baby Specialist | D93: Scotland | E93: Long Tail | F93: 21 | G93: Active | H93: Synthetic portfolio master data

Sheet Dim Date
A1: Date Dimension
A3: Date | B3: Year | C3: Quarter | D3: Month_No | E3: Month | F3: Year_Month | G3: Weekday
A4: 45658 | B4: 2025 | C4: Q1 | D4: 1 | E4: Jan | F4: 2025-01 | G4: Wednesday
A5: 45659 | B5: 2025 | C5: Q1 | D5: 1 | E5: Jan | F5: 2025-01 | G5: Thursday
A6: 45660 | B6: 2025 | C6: Q1 | D6: 1 | E6: Jan | F6: 2025-01 | G6: Friday
A7: 45661 | B7: 2025 | C7: Q1 | D7: 1 | E7: Jan | F7: 2025-01 | G7: Saturday
A8: 45662 | B8: 2025 | C8: Q1 | D8: 1 | E8: Jan | F8: 2025-01 | G8: Sunday
A9: 45663 | B9: 2025 | C9: Q1 | D9: 1 | E9: Jan | F9: 2025-01 | G9: Monday
A10: 45664 | B10: 2025 | C10: Q1 | D10: 1 | E10: Jan | F10: 2025-01 | G10: Tuesday
A11: 45665 | B11: 2025 | C11: Q1 | D11: 1 | E11: Jan | F11: 2025-01 | G11: Wednesday
A12: 45666 | B12: 2025 | C12: Q1 | D12: 1 | E12: Jan | F12: 2025-01 | G12: Thursday
A13: 45667 | B13: 2025 | C13: Q1 | D13: 1 | E13: Jan | F13: 2025-01 | G13: Friday
A14: 45668 | B14: 2025 | C14: Q1 | D14: 1 | E14: Jan | F14: 2025-01 | G14: Saturday
A15: 45669 | B15: 2025 | C15: Q1 | D15: 1 | E15: Jan | F15: 2025-01 | G15: Sunday
... A641: 46295 | B641: 2026 | C641: Q3 | D641: 9 | E641: Sep | F641: 2026-09 | G641: Wednesday

Sheet Fact Sales
A1: Fact Sales — SQL / Power BI Source Table
A3: Transaction_ID | B3: Date | C3: Customer_ID | D3: Product_ID | E3: Channel | F3: Region | G3: Customer_Tier | H3: Units | I3: List_Price | J3: Gross_Sales | K3: Discount_Pct | L3: Discount_Value | M3: Net_Revenue | N3: Unit_COGS | O3: COGS | P3: Gross_Profit | Q3: GP_Pct | R3: Freight_Rate | S3: Freight | T3: Promo_Spend | U3: Contribution_Profit | V3: Contribution_Margin | W3: Promo_Flag | X3: Source
A4: T000001 | B4: 46245 | C4: C077 | D4: P008 | E4: Baby Specialist | F4: Midlands | G4: Strategic | H4: 6 | I4: 10.28 | J4: 61.68 | K4: 0.13585923 | L4: 8.3797972 | M4: 53.300203 | N4: 4.78 | O4: 28.68 | P4: 24.620203 | Q4: 0.46191574 | R4: 0.023 | S4: 1.2259047 | T4: 0 | U4: 23.394298 | V4: 0.43891574 | W4: Non-Promo | X4: Synthetic ERP/CRM extract
A5: T000002 | B5: 45847 | C5: C078 | D5: P029 | E5: Baby Specialist | F5: Scotland | G5: Strategic | H5: 39 | I5: 5.11 | J5: 199.29 | K5: 0.12226316 | L5: 24.365826 | M5: 174.92417 | N5: 2.21 | O5: 86.19 | P5: 88.734174 | Q5: 0.50727222 | R5: 0.023 | S5: 4.023256 | T5: 4.02 | U5: 80.690918 | V5: 0.46129083 | W5: Promo | X5: Synthetic ERP/CRM extract
A6: T000003 | B6: 45788 | C6: C020 | D6: P025 | E6: Pharmacy | F6: Midlands | G6: Core | H6: 38 | I6: 11.48 | J6: 436.24 | K6: 0.13279986 | L6: 57.932612 | M6: 378.30739 | N6: 5.45 | O6: 207.1 | P6: 171.20739 | Q6: 0.45256158 | R6: 0.021 | S6: 7.9444551 | T6: 0 | U6: 163.26293 | V6: 0.43156158 | W6: Non-Promo | X6: Synthetic ERP/CRM extract
A7: T000004 | B7: 46107 | C7: C016 | D7: P028 | E7: Pharmacy | F7: Northern Ireland | G7: Strategic | H7: 40 | I7: 8.94 | J7: 357.6 | K7: 0.13896154 | L7: 49.692648 | M7: 307.90735 | N7: 4.44 | O7: 177.6 | P7: 130.30735 | Q7: 0.42320312 | R7: 0.021 | S7: 6.4660544 | T7: 0 | U7: 123.8413 | V7: 0.40220312 | W7: Non-Promo | X7: Synthetic ERP/CRM extract
A8: T000005 | B8: 46011 | C8: C074 | D8: P017 | E8: Wholesale | F8: Wales | G8: Long Tail | H8: 4 | I8: 4.55 | J8: 18.2 | K8: 0.19827505 | L8: 3.608606 | M8: 14.591394 | N8: 2.18 | O8: 8.72 | P8: 5.871394 | Q8: 0.40238746 | R8: 0.015 | S8: 0.21887091 | T8: 0 | U8: 5.6525231 | V8: 0.38738746 | W8: Non-Promo | X8: Synthetic ERP/CRM extract
A9: T000006 | B9: 46237 | C9: C018 | D9: P039 | E9: Pharmacy | F9: Scotland | G9: Strategic | H9: 119 | I9: 4.89 | J9: 581.91 | K9: 0.15588672 | L9: 90.712043 | M9: 491.19796 | N9: 2.72 | O9: 323.68 | P9: 167.51796 | Q9: 0.3410396 | R9: 0.021 | S9: 10.315157 | T9: 6.13 | U9: 151.0728 | V9: 0.30755991 | W9: Promo | X9: Synthetic ERP/CRM extract
A10: T000007 | B10: 46230 | C10: C084 | D10: P001 | E10: Baby Specialist | F10: Scotland | G10: Core | H10: 93 | I10: 10.81 | J10: 1005.33 | K10: 0.12304343 | L10: 123.69925 | M10: 881.63075 | N10: 5.77 | O10: 536.61 | P10: 345.02075 | Q10: 0.39134383 | R10: 0.023 | S10: 20.277507 | T10: 0 | U10: 324.74324 | V10: 0.36834383 | W10: Non-Promo | X10: Synthetic ERP/CRM extract
A11: T000008 | B11: 45816 | C11: C035 | D11: P015 | E11: Online Marketplace | F11: Wales | G11: Core | H11: 75 | I11: 5 | J11: 375 | K11: 0.13925785 | L11: 52.221695 | M11: 322.7783 | N11: 2.78 | O11: 208.5 | P11: 114.2783 | Q11: 0.3540458 | R11: 0.026 | S11: 8.3922359 | T11: 0 | U11: 105.88607 | V11: 0.3280458 | W11: Non-Promo | X11: Synthetic ERP/CRM extract
A12: T000009 | B12: 46045 | C12: C037 | D12: P043 | E12: Online Marketplace | F12: North | G12: Core | H12: 4 | I12: 6.01 | J12: 24.04 | K12: 0.16307852 | L12: 3.9204077 | M12: 20.119592 | N12: 3.03 | O12: 12.12 | P12: 7.9995923 | Q12: 0.39760211 | R12: 0.026 | S12: 0.5231094 | T12: 0 | U12: 7.4764829 | V12: 0.37160211 | W12: Non-Promo | X12: Synthetic ERP/CRM extract
A13: T000010 | B13: 46264 | C13: C022 | D13: P023 | E13: Pharmacy | F13: Northern Ireland | G13: Core | H13: 4 | I13: 14.31 | J13: 57.24 | K13: 0.11831834 | L13: 6.7725421 | M13: 50.467458 | N13: 7.87 | O13: 31.48 | P13: 18.987458 | Q13: 0.37623171 | R13: 0.021 | S13: 1.0598166 | T13: 0 | U13: 17.927641 | V13: 0.35523171 | W13: Non-Promo | X13: Synthetic ERP/CRM extract
A14: T000011 | B14: 46059 | C14: C079 | D14: P025 | E14: Baby Specialist | F14: Northern Ireland | G14: Core | H14: 22 | I14: 11.84 | J14: 260.48 | K14: 0.15968023 | L14: 41.593505 | M14: 218.88649 | N14: 5.77 | O14: 126.94 | P14: 91.946495 | Q14: 0.42006472 | R14: 0.023 | S14: 5.0343894 | T14: 3.17 | U14: 83.742105 | V14: 0.38258233 | W14: Promo | X14: Synthetic ERP/CRM extract
A15: T000012 | B15: 45984 | C15: C039 | D15: P032 | E15: Online Marketplace | F15: London & South East | G15: Core | H15: 27 | I15: 10.69 | J15: 288.63 | K15: 0.13080742 | L15: 37.754946 | M15: 250.87505 | N15: 4.49 | O15: 121.23 | P15: 129.64505 | Q15: 0.5167714 | R15: 0.026 | S15: 6.5227514 | T15: 0 | U15: 123.1223 | V15: 0.4907714 | W15: Non-Promo | X15: Synthetic ERP/CRM extract
... A2003: T002000 | B2003: 45722 | C2003: C054 | D2003: P028 | E2003: DTC | F2003: Scotland | G2003: Core | H2003: 103 | I2003: 8.64 | J2003: 889.92 | K2003: 0.11224057 | L2003: 99.885126 | M2003: 790.03487 | N2003: 4.27 | O2003: 439.81 | P2003: 350.22487 | Q2003: 0.44330306 | R2003: 0.045 | S2003: 35.551569 | T2003: 21.32 | U2003: 293.3533 | V2003: 0.37131691 | W2003: Promo | X2003: Synthetic ERP/CRM extract

Sheet Customer Profitability
A1: Customer Profitability — SQL Analysis
A2: Source: commercial_finance_analysis.sql / commercial_finance.db
A3: Customer_ID | B3: Customer_Name | C3: Channel | D3: Tier | E3: Net_Revenue | F3: Discount_Value | G3: Discount_Rate | H3: Gross_Profit | I3: GP_Margin | J3: Cost_to_Serve | K3: Contribution_Profit | L3: Contribution_Margin
A4: C046 | B4: Direct Family Customer 01 | C4: DTC | D4: Strategic | E4: 29695.55 | F4: 2373.27 | G4: 0.074 | H4: 13186.69 | I4: 0.4441 | J4: 1376.16 | K4: 11810.53 | L4: 0.3977
A5: C047 | B5: Direct Family Customer 02 | C5: DTC | D5: Strategic | E5: 28448 | F5: 2530.95 | G5: 0.0817 | H5: 12079.36 | I5: 0.4246 | J5: 1326.48 | K5: 10752.88 | L5: 0.378
A6: C077 | B6: LittleNest Retail 02 | C6: Baby Specialist | D6: Strategic | E6: 23824.36 | F6: 3359.4 | G6: 0.1236 | H6: 9469.62 | I6: 0.3975 | J6: 673.37 | K6: 8796.25 | L6: 0.3692
A7: C001 | B7: Northgate Grocers 01 | C7: Grocery | D7: Strategic | E7: 23314.54 | F7: 4596.2 | G7: 0.1647 | H7: 8771.86 | I7: 0.3762 | J7: 538.59 | K7: 8233.27 | L7: 0.3531
A8: C048 | B8: Direct Family Customer 03 | C8: DTC | D8: Strategic | E8: 20694.21 | F8: 1891.79 | G8: 0.0838 | H8: 9143.6 | I8: 0.4418 | J8: 1068.38 | K8: 8075.22 | L8: 0.3902
A9: C018 | B9: WellSpring Pharmacy 03 | C9: Pharmacy | D9: Strategic | E9: 20045.68 | F9: 3146.25 | G9: 0.1357 | H9: 8185.65 | I9: 0.4083 | J9: 519.51 | K9: 7666.14 | L9: 0.3824
A10: C078 | B10: LittleNest Retail 03 | C10: Baby Specialist | D10: Strategic | E10: 19839.5 | F10: 2585.81 | G10: 0.1153 | H10: 7949.65 | I10: 0.4007 | J10: 496.64 | K10: 7453.01 | L10: 0.3757
A11: C031 | B11: HomeCart Online 01 | C11: Online Marketplace | D11: Strategic | E11: 21393.98 | F11: 4485.42 | G11: 0.1733 | H11: 8060.27 | I11: 0.3768 | J11: 761.83 | K11: 7298.43 | L11: 0.3411
A12: C017 | B12: WellSpring Pharmacy 02 | C12: Pharmacy | D12: Strategic | E12: 19566.79 | F12: 2828.5 | G12: 0.1263 | H12: 7588.89 | I12: 0.3878 | J12: 435.84 | K12: 7153.05 | L12: 0.3656
A13: C032 | B13: HomeCart Online 02 | C13: Online Marketplace | D13: Strategic | E13: 20627.81 | F13: 4282.95 | G13: 0.1719 | H13: 7451.06 | I13: 0.3612 | J13: 616.4 | K13: 6834.65 | L13: 0.3313
A14: C016 | B14: WellSpring Pharmacy 01 | C14: Pharmacy | D14: Strategic | E14: 17060.87 | F14: 2566.29 | G14: 0.1308 | H14: 7131.68 | I14: 0.418 | J14: 408.83 | K14: 6722.85 | L14: 0.3941
A15: C033 | B15: HomeCart Online 03 | C15: Online Marketplace | D15: Strategic | E15: 21060.26 | F15: 4610.84 | G15: 0.1796 | H15: 7309.75 | I15: 0.3471 | J15: 659.78 | K15: 6649.98 | L15: 0.3158
... A93: C045 | B93: HomeCart Online 15 | C93: Online Marketplace | D93: Long Tail | E93: 469.64 | F93: 73.89 | G93: 0.1359 | H93: 156.06 | I93: 0.3323 | J93: 12.21 | K93: 143.85 | L93: 0.3063

Sheet Product Profitability
A1: Product / SKU Profitability — SQL Analysis
A2: Source: commercial_finance_analysis.sql / commercial_finance.db
A3: Product_ID | B3: SKU_Name | C3: Brand | D3: Category | E3: Net_Revenue | F3: Units | G3: ASP | H3: Gross_Profit | I3: GP_Margin | J3: Promo_Spend | K3: Contribution_Profit | L3: Contribution_Margin
A4: P026 | B4: PureNest Diapers 40 pack | C4: PureNest | D4: Diapers | E4: 53279.74 | F4: 3466 | G4: 15.37 | H4: 23087.21 | I4: 0.4333 | J4: 103.59 | K4: 21637.14 | L4: 0.4061
A5: P014 | B5: LittleBloom Diapers 40 pack | C5: LittleBloom | D5: Diapers | E5: 46531.07 | F5: 3428 | G5: 13.57 | H5: 16855.56 | I5: 0.3622 | J5: 132.99 | K5: 15517.58 | L5: 0.3335
A6: P028 | B6: PureNest Wipes 8 pack | C6: PureNest | D6: Wipes | E6: 34065.07 | F6: 4431 | G6: 7.69 | H6: 14878.13 | I6: 0.4368 | J6: 194.05 | K6: 13760.7 | L6: 0.404
A7: P025 | B7: PureNest Diapers 24 pack | C7: PureNest | D7: Diapers | E7: 34328.82 | F7: 3487 | G7: 9.84 | H7: 14525.29 | I7: 0.4231 | J7: 165.8 | K7: 13533.55 | L7: 0.3942
A8: P002 | B8: Nurtura Diapers 40 pack | C8: Nurtura | D8: Diapers | E8: 36042.26 | F8: 2488 | G8: 14.49 | H8: 14229.28 | I8: 0.3948 | J8: 78.52 | K8: 13101.81 | L8: 0.3635
A9: P001 | B9: Nurtura Diapers 24 pack | C9: Nurtura | D9: Diapers | E9: 35430.98 | F9: 3864 | G9: 9.17 | H9: 13615.88 | I9: 0.3843 | J9: 88.11 | K9: 12637.6 | L9: 0.3567
A10: P038 | B10: TinySteps Diapers 40 pack | C10: TinySteps | D10: Diapers | E10: 37222.21 | F10: 2874 | G10: 12.95 | H10: 10430.42 | I10: 0.2802 | J10: 99.74 | K10: 9465.25 | L10: 0.2543
A11: P037 | B11: TinySteps Diapers 24 pack | C11: TinySteps | D11: Diapers | E11: 29819.92 | F11: 3574 | G11: 8.34 | H11: 9626.87 | I11: 0.3228 | J11: 159.65 | K11: 8651.13 | L11: 0.2901
A12: P004 | B12: Nurtura Wipes 8 pack | C12: Nurtura | D12: Wipes | E12: 21286.1 | F12: 3057 | G12: 6.96 | H12: 8539.65 | I12: 0.4012 | J12: 111.79 | K12: 7956.89 | L12: 0.3738
A13: P013 | B13: LittleBloom Diapers 24 pack | C13: LittleBloom | D13: Diapers | E13: 25714.65 | F13: 2908 | G13: 8.84 | H13: 8349.22 | I13: 0.3247 | J13: 99.21 | K13: 7615.22 | L13: 0.2961
A14: P030 | B14: PureNest Baby Bath 500ml | C14: PureNest | D14: Baby Bath | E14: 14568.73 | F14: 2041 | G14: 7.14 | H14: 7306.46 | I14: 0.5015 | J14: 56.18 | K14: 6855.49 | L14: 0.4706
A15: P003 | B15: Nurtura Wipes 4 pack | C15: Nurtura | D15: Wipes | E15: 17000.32 | F15: 3687 | G15: 4.61 | H15: 6676.91 | I15: 0.3928 | J15: 18.68 | K15: 6205.39 | L15: 0.365
... A51: P023 | B51: LittleBloom Nursery Single | C51: LittleBloom | D51: Nursery | E51: 1706.82 | F51: 138 | G51: 12.37 | H51: 656.51 | I51: 0.3846 | J51: 0 | K51: 599.86 | L51: 0.3515

Sheet Channel Analysis
A1: Channel Commercial Performance — SQL Analysis
A2: Source: commercial_finance_analysis.sql / commercial_finance.db
A3: Channel | B3: Net_Revenue | C3: Gross_Profit | D3: GP_Margin | E3: Discount_Value | F3: Discount_Rate | G3: Freight | H3: Promo_Spend | I3: Contribution_Profit | J3: Contribution_Margin
A4: DTC | B4: 128367.88 | C4: 56279.12 | D4: 0.4384 | E4: 10161.52 | F4: 0.0734 | G4: 5776.55 | H4: 342.25 | I4: 50160.32 | J4: 0.3908
A5: Baby Specialist | B5: 107222.88 | C5: 43215.94 | D5: 0.403 | E5: 13422.03 | F5: 0.1113 | G5: 2466.13 | H5: 322.29 | I5: 40427.52 | J5: 0.377
A6: Pharmacy | B6: 105922.65 | C6: 42866.38 | D6: 0.4047 | E6: 14666.02 | F6: 0.1216 | G6: 2224.38 | H6: 274.8 | I6: 40367.2 | J6: 0.3811
A7: Online Marketplace | B7: 105031.64 | C7: 38768.25 | D7: 0.3691 | E7: 21202.02 | F7: 0.168 | G7: 2730.82 | H7: 625.63 | I7: 35411.8 | J7: 0.3372
A8: Wholesale | B8: 97328.96 | C8: 34525.81 | D8: 0.3547 | E8: 22874.1 | F8: 0.1903 | G8: 1459.93 | H8: 247.65 | I8: 32818.23 | J8: 0.3372
A9: Grocery | B9: 88907.46 | C9: 33881.58 | D9: 0.3811 | E9: 15722.4 | F9: 0.1503 | G9: 1600.33 | H9: 402.51 | I9: 31878.73 | J9: 0.3586

Sheet Category Analysis
A1: Category Profitability — SQL Analysis
A2: Source: commercial_finance_analysis.sql / commercial_finance.db
A3: Category | B3: Net_Revenue | C3: Gross_Profit | D3: GP_Margin | E3: Contribution_Profit | F3: Contribution_Margin
A4: Diapers | B4: 298369.65 | C4: 110719.73 | D4: 0.3711 | E4: 102159.29 | F4: 0.3424
A5: Wipes | B5: 143676.81 | C5: 56197.4 | D5: 0.3911 | E5: 51973.18 | F5: 0.3617
A6: Baby Bath | B6: 62975.51 | C6: 28598.19 | D6: 0.4541 | E6: 26609.47 | F6: 0.4225
A7: Skincare | B7: 57161.69 | C7: 26389.12 | D7: 0.4617 | E7: 24612.23 | F7: 0.4306
A8: Feeding | B8: 42507.21 | C8: 17466.87 | D8: 0.4109 | E8: 16294.99 | F8: 0.3833
A9: Nursery | B9: 28090.59 | C9: 10165.76 | D9: 0.3619 | E9: 9414.64 | F9: 0.3352

Sheet Monthly Trend
A1: Monthly Commercial Trend — SQL Analysis
A2: Source: commercial_finance_analysis.sql / commercial_finance.db
A3: Year_Month | B3: Net_Revenue | C3: Gross_Profit | D3: GP_Margin | E3: Discount_Value | F3: Discount_Rate | G3: Promo_Spend | H3: Contribution_Profit | I3: Contribution_Margin | J3: Units | K3: ASP
A4: 2025-01 | B4: 29504.47 | C4: 11666.09 | D4: 0.3954 | E4: 4037.12 | F4: 0.1204 | G4: 61.32 | H4: 10754.07 | I4: 0.3645 | J4: 3418 | K4: 8.63
A5: 2025-02 | B5: 22669.04 | C5: 8788.03 | D5: 0.3877 | E5: 3294.31 | F5: 0.1269 | G5: 85.62 | H5: 8101.37 | I5: 0.3574 | J5: 2887 | K5: 7.85
A6: 2025-03 | B6: 42015.55 | C6: 16786.02 | D6: 0.3995 | E6: 6354.03 | F6: 0.1314 | G6: 122.83 | H6: 15592.97 | I6: 0.3711 | J6: 5070 | K6: 8.29
A7: 2025-04 | B7: 24286.62 | C7: 9929.36 | D7: 0.4088 | E7: 3889.74 | F7: 0.138 | G7: 122.27 | H7: 9209.56 | I7: 0.3792 | J7: 3428 | K7: 7.08
A8: 2025-05 | B8: 23245.07 | C8: 9276.12 | D8: 0.3991 | E8: 3639.76 | F8: 0.1354 | G8: 76.43 | H8: 8621.69 | I8: 0.3709 | J8: 2903 | K8: 8.01
A9: 2025-06 | B9: 27675.55 | C9: 10927.16 | D9: 0.3948 | E9: 3930.4 | F9: 0.1244 | G9: 99.09 | H9: 10122.15 | I9: 0.3657 | J9: 3373 | K9: 8.21
A10: 2025-07 | B10: 28634.19 | C10: 11604.6 | D10: 0.4053 | E10: 4669.16 | F10: 0.1402 | G10: 91.31 | H10: 10813.99 | I10: 0.3777 | J10: 3753 | K10: 7.63
A11: 2025-08 | B11: 26049.87 | C11: 10099.82 | D11: 0.3877 | E11: 4206.83 | F11: 0.139 | G11: 77.19 | H11: 9374.38 | I11: 0.3599 | J11: 3219 | K11: 8.09
A12: 2025-09 | B12: 30432 | C12: 12130.79 | D12: 0.3986 | E12: 4575.6 | F12: 0.1307 | G12: 102.24 | H12: 11226.15 | I12: 0.3689 | J12: 3943 | K12: 7.72
A13: 2025-10 | B13: 34970.59 | C13: 14150.65 | D13: 0.4046 | E13: 5658.13 | F13: 0.1393 | G13: 165.67 | H13: 13136.11 | I13: 0.3756 | J13: 4482 | K13: 7.8
A14: 2025-11 | B14: 46752.4 | C14: 18024.49 | D14: 0.3855 | E14: 7433.61 | F14: 0.1372 | G14: 122.56 | H14: 16737.11 | I14: 0.358 | J14: 5804 | K14: 8.06
A15: 2025-12 | B15: 24489.08 | C15: 9861 | D15: 0.4027 | E15: 4133.3 | F15: 0.1444 | G15: 75.58 | H15: 9197.89 | I15: 0.3756 | J15: 3172 | K15: 7.72
... A24: 2026-09 | B24: 31916.85 | C24: 12265.47 | D24: 0.3843 | E24: 4955.64 | F24: 0.1344 | G24: 82.42 | H24: 11351.21 | I24: 0.3556 | J24: 3704 | K24: 8.62

Sheet Dashboard
A1: Commercial Finance Dashboard — Pricing, Margin & Profitability
A3: SQL-powered commercial analysis | Jan-2025 to Sep-2026 | Synthetic FMCG portfolio
A5: Net Revenue | D5: Gross Profit | G5: Gross Margin | J5: Contribution Profit
A6: ="£"&TEXT(SUM('Channel Analysis'!B4:B9),"#,##0") -> £632,781 | D6: ="£"&TEXT(SUM('Channel Analysis'!C4:C9),"#,##0") -> £249,537 | G6: =TEXT(SUM('Channel Analysis'!C4:C9)/SUM('Channel Analysis'!B4:B9),"0.0%") -> 39.4% | J6: ="£"&TEXT(SUM('Channel Analysis'!I4:I9),"#,##0") -> £231,064
A9: Contribution Margin | D9: Discount Value | G9: Discount Rate | J9: Promo Spend
A10: =TEXT(SUM('Channel Analysis'!I4:I9)/SUM('Channel Analysis'!B4:B9),"0.0%") -> 36.5% | D10: ="£"&TEXT(SUM('Channel Analysis'!E4:E9),"#,##0") -> £98,048 | G10: =TEXT(SUM('Channel Analysis'!E4:E9)/(SUM('Channel Analysis'!B4:B9)+SUM('Channel Analysis'!E4:E9)),"0.0%") -> 13.4% | J10: ="£"&TEXT(SUM('Channel Analysis'!H4:H9),"#,##0") -> £2,215
A14: Monthly Commercial Trend
A15: Month | B15: Net Revenue | C15: Contribution Margin
A16: 2025-01 | B16: 29504.47 | C16: 0.3645
A17: 2025-02 | B17: 22669.04 | C17: 0.3574
A18: 2025-03 | B18: 42015.55 | C18: 0.3711
A19: 2025-04 | B19: 24286.62 | C19: 0.3792
A20: 2025-05 | B20: 23245.07 | C20: 0.3709
A21: 2025-06 | B21: 27675.55 | C21: 0.3657
A22: 2025-07 | B22: 28634.19 | C22: 0.3777
A23: 2025-08 | B23: 26049.87 | C23: 0.3599
A24: 2025-09 | B24: 30432 | C24: 0.3689 | H24: Channel Contribution Performance
A25: 2025-10 | B25: 34970.59 | C25: 0.3756 | H25: Channel | I25: Contribution Profit | J25: Contribution Margin
A26: 2025-11 | B26: 46752.4 | C26: 0.358 | H26: DTC | I26: 50160.32 | J26: 0.3908
A27: 2025-12 | B27: 24489.08 | C27: 0.3756 | H27: Baby Specialist | I27: 40427.52 | J27: 0.377
A28: 2026-01 | B28: 22723.12 | C28: 0.3573 | H28: Pharmacy | I28: 40367.2 | J28: 0.3811
A29: 2026-02 | B29: 20706.29 | C29: 0.3642 | H29: Online Marketplace | I29: 35411.8 | J29: 0.3372
A30: 2026-03 | B30: 46197.59 | C30: 0.3645 | H30: Wholesale | I30: 32818.23 | J30: 0.3372
A31: 2026-04 | B31: 33429.4 | C31: 0.3784 | H31: Grocery | I31: 31878.73 | J31: 0.3586
A32: 2026-05 | B32: 30923.21 | C32: 0.3677
A33: 2026-06 | B33: 26369 | C33: 0.3438
A34: 2026-07 | B34: 28712.72 | C34: 0.3555 | H34: Category Profitability
A35: 2026-08 | B35: 31078.9 | C35: 0.3549 | H35: Category | I35: Net Revenue | J35: Contribution Profit | K35: Contribution Margin
A36: 2026-09 | B36: 31916.85 | C36: 0.3556 | H36: Diapers | I36: 298369.65 | J36: 102159.29 | K36: 0.3424
H37: Wipes | I37: 143676.81 | J37: 51973.18 | K37: 0.3617
H38: Baby Bath | I38: 62975.51 | J38: 26609.47 | K38: 0.4225
H39: Skincare | I39: 57161.69 | J39: 24612.23 | K39: 0.4306
H40: Feeding | I40: 42507.21 | J40: 16294.99 | K40: 0.3833
H41: Nursery | I41: 28090.59 | J41: 9414.64 | K41: 0.3352
A61: Management interpretation prompts
A62: 1 | B62: Which channels create the most contribution profit—not just revenue?
A63: 2 | B63: Where is discounting eroding commercial value?
A64: 3 | B64: Which categories have strong revenue but weak contribution margin?
A65: 4 | B65: Which customers require repricing, lower discounts or cost-to-serve action?
A66: 5 | B66: Which commercial actions should be prioritised before the next pricing round?

Sheet Data Dictionary
A1: Data Dictionary & Commercial Definitions
A3: Field / Metric | B3: Definition | C3: Unit | D3: Layer | E3: Primary Table | F3: Commercial Relevance | G3: Source
A4: Gross Sales | B4: Units × list price before discount | C4: £ | D4: Fact | E4: Fact Sales | F4: Starting sales value | G4: Synthetic ERP extract
A5: Discount % | B5: Discount as % gross sales | C5: % | D5: Fact | E5: Fact Sales | F5: Pricing governance | G5: Synthetic ERP extract
A6: Net Revenue | B6: Gross sales less discount | C6: £ | D6: Fact | E6: Fact Sales | F6: Realised revenue | G6: Calculated in data pipeline
A7: COGS | B7: Units × unit COGS | C7: £ | D7: Fact | E7: Fact Sales | F7: Product economics | G7: Calculated in data pipeline
A8: Gross Profit | B8: Net revenue − COGS | C8: £ | D8: Fact | E8: Fact Sales | F8: Product margin | G8: Calculated in data pipeline
A9: Gross Margin | B9: Gross profit / net revenue | C9: % | D9: Analysis | E9: SQL outputs | F9: Profitability KPI | G9: SQL
A10: Freight | B10: Channel freight rate × net revenue | C10: £ | D10: Fact | E10: Fact Sales | F10: Cost-to-serve | G10: Calculated in data pipeline
A11: Promo Spend | B11: Promotional support cost | C11: £ | D11: Fact | E11: Fact Sales | F11: Trade investment | G11: Synthetic input
A12: Contribution Profit | B12: GP − freight − promo spend | C12: £ | D12: Analysis | E12: SQL outputs | F12: Commercial value | G12: SQL
A13: Contribution Margin | B13: Contribution profit / net revenue | C13: % | D13: Analysis | E13: SQL outputs | F13: Commercial Finance KPI | G13: SQL
A14: Customer Tier | B14: Strategic / Core / Long Tail | C14: text | D14: Dimension | E14: Dim Customer | F14: Segmentation | G14: Synthetic master data
A15: Channel | B15: Route to market | C15: text | D15: Dimension | E15: Dim Customer | F15: Route-to-market economics | G15: Synthetic master data
A18: V2 Metrics
A19: Target Discount | B19: Synthetic pricing-policy benchmark by channel, tier and promo mix | C19: % | D19: Formula / assumption | E19: Discount Leakage | F19: Pricing governance | G19: Portfolio assumption
A20: Discount Leakage | B20: Gross sales × max(actual discount − target discount, 0) | C20: £ | D20: Formula | E20: Discount Leakage | F20: Potential pricing leakage | G20: Modelled, not realised
A21: Potential Recapture | B21: Discount leakage × realisation factor | C21: £ | D21: Formula | E21: Discount Leakage | F21: Repricing opportunity | G21: 70% synthetic realisation assumption
A22: Customer Quadrant | B22: Revenue / contribution-margin matrix classification | C22: text | D22: Formula | E22: Customer Matrix | F22: Customer strategy | G22: Median thresholds
A23: Promo ROI Proxy | B23: Incremental contribution proxy / promo spend | C23: x | D23: Derived | E23: Promo Effectiveness | F23: Promotion efficiency | G23: Observational; not causal
A24: Revenue HHI | B24: Sum of squared customer revenue shares | C24: index | D24: Derived | E24: Customer Concentration | F24: Concentration diagnostic | G24: Synthetic portfolio
A25: SKU Portfolio Action | B25: Revenue / margin quadrant classification | C25: text | D25: Formula | E25: SKU Rationalisation | F25: Portfolio prioritisation | G25: Median thresholds
A26: Price Effect | B26: Current units × change in ASP | C26: £ | D26: Formula | E26: PVM Analysis V2 | F26: Price realisation | G26: YTD 2026 vs YTD 2025
A27: Volume Effect | B27: Change in total units × prior mix × prior ASP | C27: £ | D27: Formula | E27: PVM Analysis V2 | F27: Volume growth | G27: YTD 2026 vs YTD 2025
A28: Mix Effect | B28: Current total units × change in category mix × prior ASP | C28: £ | D28: Formula | E28: PVM Analysis V2 | F28: Portfolio mix | G28: YTD 2026 vs YTD 2025
A31: V3 Metrics
A32: Excess Discount Recovery | B32: Share of customer discount above policy assumed to be recovered | C32: % | D32: Scenario input | E32: Pricing Scenarios | F32: Repricing scenario | G32: Conservative / Base / Stretch
A33: Volume Retention | B33: Share of volume assumed to remain after repricing | C33: % | D33: Scenario input | E33: Pricing Scenarios | F33: Repricing risk | G33: Synthetic scenario assumption
A34: Price Recapture on Retained Business | B34: Leakage × recovery % × retention % | C34: £ | D34: Formula | E34: Pricing Scenarios | F34: Price upside | G34: Modelled
A35: Contribution Lost from Attrition | B35: Existing contribution × (1 − retention %) | C35: £ | D35: Formula | E35: Pricing Scenarios | F35: Downside risk | G35: Modelled
A36: Net Contribution Uplift | B36: Price recapture less contribution lost from attrition | C36: £ | D36: Formula | E36: Pricing Scenarios | F36: Risk-adjusted repricing value | G36: Modelled
A37: Customer Action Register | B37: Prioritised customer actions with owner, status and timing | C37: workflow | D37: Input / linked | E37: Customer Action Register | F37: Commercial cadence | G37: Portfolio workflow

Sheet Power BI Measures
A1: Power BI Measure Library — V1
A3: Prepared DAX measures for the later Power BI build. V1 is Power BI-ready; a PBIX dashboard is not yet claimed.
A5: Measure | B5: DAX | C5: Purpose
A6: Net Revenue | B6: Net Revenue = SUM(FactSales[Net_Revenue]) | C6: Commercial revenue
A7: Gross Profit | B7: Gross Profit = SUM(FactSales[Gross_Profit]) | C7: Product margin
A8: Gross Margin % | B8: Gross Margin % = DIVIDE([Gross Profit],[Net Revenue]) | C8: Margin rate
A9: Discount Value | B9: Discount Value = SUM(FactSales[Discount_Value]) | C9: Discount leakage
A10: Discount Rate % | B10: Discount Rate % = DIVIDE([Discount Value],[Net Revenue]+[Discount Value]) | C10: Discount intensity
A11: Promo Spend | B11: Promo Spend = SUM(FactSales[Promo_Spend]) | C11: Trade investment
A12: Contribution Profit | B12: Contribution Profit = SUM(FactSales[Contribution_Profit]) | C12: Profit after cost-to-serve
A13: Contribution Margin % | B13: Contribution Margin % = DIVIDE([Contribution Profit],[Net Revenue]) | C13: Commercial profitability
A14: Units | B14: Units = SUM(FactSales[Units]) | C14: Volume
A15: ASP | B15: ASP = DIVIDE([Net Revenue],[Units]) | C15: Realised selling price

Sheet Discount Leakage
A1: Discount Leakage & Repricing Opportunities
A3: Pricing-policy benchmark is synthetic. Potential recapture applies a 70% realisation factor and is not a realised saving.
A5: Customer ID | B5: Customer Name | C5: Channel | D5: Tier | E5: Gross Sales (£) | F5: Actual Discount % | G5: Base Target % | H5: Tier Premium % | I5: Promo Gross Share % | J5: Promo Adjustment % | K5: Target Discount % | L5: Excess Discount % | M5: Gross Leakage (£) | N5: Recapture Factor | O5: Potential Recapture (£) | P5: Contribution Margin | Q5: Commercial Action
A6: C001 | B6: Northgate Grocers 01 | C6: Grocery | D6: Strategic | E6: 27910.74 | F6: 0.16467481 | G6: =IFERROR(VLOOKUP(C6,Assumptions!$A$23:$B$28,2,FALSE),0) -> 0.12 | H6: =IF(D6="Strategic",Assumptions!$B$31,IF(D6="Core",Assumptions!$B$32,Assumptions!$B$33)) -> 0.02 | I6: 0.25106715 | J6: =I6*Assumptions!$B$34 -> 0.005021343 | K6: =G6+H6+J6 -> 0.14502134 | L6: =MAX(F6-K6,0) -> 0.019653466 | M6: =E6*L6 -> 548.54277 | N6: =Assumptions!$B$35 -> 0.7 | O6: =M6*N6 -> 383.97994 | P6: 0.3531389 | Q6: =IF(O6>=100,"Priority repricing",IF(L6>=1%,"Review discount","Within policy")) -> Priority repricing
A7: C061 | B7: FamilyCare Wholesale 01 | C7: Wholesale | D7: Strategic | E7: 21132.51 | F7: 0.2090308 | G7: =IFERROR(VLOOKUP(C7,Assumptions!$A$23:$B$28,2,FALSE),0) -> 0.16 | H7: =IF(D7="Strategic",Assumptions!$B$31,IF(D7="Core",Assumptions!$B$32,Assumptions!$B$33)) -> 0.02 | I7: 0.30271747 | J7: =I7*Assumptions!$B$34 -> 0.0060543494 | K7: =G7+H7+J7 -> 0.18605435 | L7: =MAX(F7-K7,0) -> 0.022976448 | M7: =E7*L7 -> 485.55001 | N7: =Assumptions!$B$35 -> 0.7 | O7: =M7*N7 -> 339.88501 | P7: 0.33949155 | Q7: =IF(O7>=100,"Priority repricing",IF(L7>=1%,"Review discount","Within policy")) -> Priority repricing
A8: C063 | B8: FamilyCare Wholesale 03 | C8: Wholesale | D8: Strategic | E8: 22454.98 | F8: 0.1993856 | G8: =IFERROR(VLOOKUP(C8,Assumptions!$A$23:$B$28,2,FALSE),0) -> 0.16 | H8: =IF(D8="Strategic",Assumptions!$B$31,IF(D8="Core",Assumptions!$B$32,Assumptions!$B$33)) -> 0.02 | I8: 0.070433374 | J8: =I8*Assumptions!$B$34 -> 0.0014086675 | K8: =G8+H8+J8 -> 0.18140867 | L8: =MAX(F8-K8,0) -> 0.017976934 | M8: =E8*L8 -> 403.67168 | N8: =Assumptions!$B$35 -> 0.7 | O8: =M8*N8 -> 282.57018 | P8: 0.33092259 | Q8: =IF(O8>=100,"Priority repricing",IF(L8>=1%,"Review discount","Within policy")) -> Priority repricing
A9: C033 | B9: HomeCart Online 03 | C9: Online Marketplace | D9: Strategic | E9: 25671.1 | F9: 0.179612 | G9: =IFERROR(VLOOKUP(C9,Assumptions!$A$23:$B$28,2,FALSE),0) -> 0.14 | H9: =IF(D9="Strategic",Assumptions!$B$31,IF(D9="Core",Assumptions!$B$32,Assumptions!$B$33)) -> 0.02 | I9: 0.26805006 | J9: =I9*Assumptions!$B$34 -> 0.0053610013 | K9: =G9+H9+J9 -> 0.165361 | L9: =MAX(F9-K9,0) -> 0.014250999 | M9: =E9*L9 -> 365.83883 | N9: =Assumptions!$B$35 -> 0.7 | O9: =M9*N9 -> 256.08718 | P9: 0.31575939 | Q9: =IF(O9>=100,"Priority repricing",IF(L9>=1%,"Review discount","Within policy")) -> Priority repricing
A10: C047 | B10: Direct Family Customer 02 | C10: DTC | D10: Strategic | E10: 30978.95 | F10: 0.081698949 | G10: =IFERROR(VLOOKUP(C10,Assumptions!$A$23:$B$28,2,FALSE),0) -> 0.05 | H10: =IF(D10="Strategic",Assumptions!$B$31,IF(D10="Core",Assumptions!$B$32,Assumptions!$B$33)) -> 0.02 | I10: 0.094512564 | J10: =I10*Assumptions!$B$34 -> 0.0018902513 | K10: =G10+H10+J10 -> 0.071890251 | L10: =MAX(F10-K10,0) -> 0.0098086982 | M10: =E10*L10 -> 303.86317 | N10: =Assumptions!$B$35 -> 0.7 | O10: =M10*N10 -> 212.70422 | P10: 0.37798374 | Q10: =IF(O10>=100,"Priority repricing",IF(L10>=1%,"Review discount","Within policy")) -> Priority repricing
A11: C018 | B11: WellSpring Pharmacy 03 | C11: Pharmacy | D11: Strategic | E11: 23191.93 | F11: 0.13566147 | G11: =IFERROR(VLOOKUP(C11,Assumptions!$A$23:$B$28,2,FALSE),0) -> 0.1 | H11: =IF(D11="Strategic",Assumptions!$B$31,IF(D11="Core",Assumptions!$B$32,Assumptions!$B$33)) -> 0.02 | I11: 0.24910863 | J11: =I11*Assumptions!$B$34 -> 0.0049821727 | K11: =G11+H11+J11 -> 0.12498217 | L11: =MAX(F11-K11,0) -> 0.010679294 | M11: =E11*L11 -> 247.67345 | N11: =Assumptions!$B$35 -> 0.7 | O11: =M11*N11 -> 173.37141 | P11: 0.38243352 | Q11: =IF(O11>=100,"Priority repricing",IF(L11>=1%,"Review discount","Within policy")) -> Priority repricing
A12: C077 | B12: LittleNest Retail 02 | C12: Baby Specialist | D12: Strategic | E12: 27183.76 | F12: 0.12358106 | G12: =IFERROR(VLOOKUP(C12,Assumptions!$A$23:$B$28,2,FALSE),0) -> 0.09 | H12: =IF(D12="Strategic",Assumptions!$B$31,IF(D12="Core",Assumptions!$B$32,Assumptions!$B$33)) -> 0.02 | I12: 0.24823093 | J12: =I12*Assumptions!$B$34 -> 0.0049646186 | K12: =G12+H12+J12 -> 0.11496462 | L12: =MAX(F12-K12,0) -> 0.0086164408 | M12: =E12*L12 -> 234.22726 | N12: =Assumptions!$B$35 -> 0.7 | O12: =M12*N12 -> 163.95908 | P12: 0.36921248 | Q12: =IF(O12>=100,"Priority repricing",IF(L12>=1%,"Review discount","Within policy")) -> Priority repricing
A13: C032 | B13: HomeCart Online 02 | C13: Online Marketplace | D13: Strategic | E13: 24910.76 | F13: 0.17193183 | G13: =IFERROR(VLOOKUP(C13,Assumptions!$A$23:$B$28,2,FALSE),0) -> 0.14 | H13: =IF(D13="Strategic",Assumptions!$B$31,IF(D13="Core",Assumptions!$B$32,Assumptions!$B$33)) -> 0.02 | I13: 0.18215582 | J13: =I13*Assumptions!$B$34 -> 0.0036431165 | K13: =G13+H13+J13 -> 0.16364312 | L13: =MAX(F13-K13,0) -> 0.0082887136 | M13: =E13*L13 -> 206.47815 | N13: =Assumptions!$B$35 -> 0.7 | O13: =M13*N13 -> 144.53471 | P13: 0.33133209 | Q13: =IF(O13>=100,"Priority repricing",IF(L13>=1%,"Review discount","Within policy")) -> Priority repricing
A14: C062 | B14: FamilyCare Wholesale 02 | C14: Wholesale | D14: Strategic | E14: 19253.07 | F14: 0.19087436 | G14: =IFERROR(VLOOKUP(C14,Assumptions!$A$23:$B$28,2,FALSE),0) -> 0.16 | H14: =IF(D14="Strategic",Assumptions!$B$31,IF(D14="Core",Assumptions!$B$32,Assumptions!$B$33)) -> 0.02 | I14: 0.070660939 | J14: =I14*Assumptions!$B$34 -> 0.0014132188 | K14: =G14+H14+J14 -> 0.18141322 | L14: =MAX(F14-K14,0) -> 0.0094611437 | M14: =E14*L14 -> 182.15606 | N14: =Assumptions!$B$35 -> 0.7 | O14: =M14*N14 -> 127.50924 | P14: 0.30827919 | Q14: =IF(O14>=100,"Priority repricing",IF(L14>=1%,"Review discount","Within policy")) -> Priority repricing
A15: C048 | B15: Direct Family Customer 03 | C15: DTC | D15: Strategic | E15: 22586 | F15: 0.083759327 | G15: =IFERROR(VLOOKUP(C15,Assumptions!$A$23:$B$28,2,FALSE),0) -> 0.05 | H15: =IF(D15="Strategic",Assumptions!$B$31,IF(D15="Core",Assumptions!$B$32,Assumptions!$B$33)) -> 0.02 | I15: 0.32381165 | J15: =I15*Assumptions!$B$34 -> 0.0064762331 | K15: =G15+H15+J15 -> 0.076476233 | L15: =MAX(F15-K15,0) -> 0.0072830935 | M15: =E15*L15 -> 164.49595 | N15: =Assumptions!$B$35 -> 0.7 | O15: =M15*N15 -> 115.14717 | P15: 0.39021647 | Q15: =IF(O15>=100,"Priority repricing",IF(L15>=1%,"Review discount","Within policy")) -> Priority repricing
A16: C016 | B16: WellSpring Pharmacy 01 | C16: Pharmacy | D16: Strategic | E16: 19627.16 | F16: 0.13075218 | G16: =IFERROR(VLOOKUP(C16,Assumptions!$A$23:$B$28,2,FALSE),0) -> 0.1 | H16: =IF(D16="Strategic",Assumptions!$B$31,IF(D16="Core",Assumptions!$B$32,Assumptions!$B$33)) -> 0.02 | I16: 0.1426727 | J16: =I16*Assumptions!$B$34 -> 0.0028534541 | K16: =G16+H16+J16 -> 0.12285345 | L16: =MAX(F16-K16,0) -> 0.0078987282 | M16: =E16*L16 -> 155.0296 | N16: =Assumptions!$B$35 -> 0.7 | O16: =M16*N16 -> 108.52072 | P16: 0.3940508 | Q16: =IF(O16>=100,"Priority repricing",IF(L16>=1%,"Review discount","Within policy")) -> Priority repricing
A17: C008 | B17: Northgate Grocers 08 | C17: Grocery | D17: Core | E17: 8306.34 | F17: 0.15201467 | G17: =IFERROR(VLOOKUP(C17,Assumptions!$A$23:$B$28,2,FALSE),0) -> 0.12 | H17: =IF(D17="Strategic",Assumptions!$B$31,IF(D17="Core",Assumptions!$B$32,Assumptions!$B$33)) -> 0.01 | I17: 0.30981636 | J17: =I17*Assumptions!$B$34 -> 0.0061963271 | K17: =G17+H17+J17 -> 0.13619633 | L17: =MAX(F17-K17,0) -> 0.015818346 | M17: =E17*L17 -> 131.39256 | N17: =Assumptions!$B$35 -> 0.7 | O17: =M17*N17 -> 91.974791 | P17: 0.36201643 | Q17: =IF(O17>=100,"Priority repricing",IF(L17>=1%,"Review discount","Within policy")) -> Review discount
... A95: C089 | B95: LittleNest Retail 14 | C95: Baby Specialist | D95: Long Tail | E95: 1266.57 | F95: 0.089839874 | G95: =IFERROR(VLOOKUP(C95,Assumptions!$A$23:$B$28,2,FALSE),0) -> 0.09 | H95: =IF(D95="Strategic",Assumptions!$B$31,IF(D95="Core",Assumptions!$B$32,Assumptions!$B$33)) -> 0 | I95: 0 | J95: =I95*Assumptions!$B$34 -> 0 | K95: =G95+H95+J95 -> 0.09 | L95: =MAX(F95-K95,0) -> 0 | M95: =E95*L95 -> 0 | N95: =Assumptions!$B$35 -> 0.7 | O95: =M95*N95 -> 0 | P95: 0.37547231 | Q95: =IF(O95>=100,"Priority repricing",IF(L95>=1%,"Review discount","Within policy")) -> Within policy
A99: Leakage summary | H99: Customer | I99: Potential Recapture (£)
A100: Metric | B100: Value | C100: Interpretation | D100: Source | H100: Northgate Grocers 01 | I100: =O6 -> 383.97994
A101: Gross Discount Leakage | B101: =SUM(M6:M95) -> 5536.2442 | C101: Amount above synthetic pricing policy | D101: Calculated | H101: FamilyCare Wholesale 01 | I101: =O7 -> 339.88501
A102: Potential Recapture | B102: =SUM(O6:O95) -> 3875.371 | C102: 70% modelled realisation of leakage | D102: Calculated | H102: FamilyCare Wholesale 03 | I102: =O8 -> 282.57018
A103: Priority Repricing Accounts | B103: =COUNTIF(Q6:Q95,"Priority repricing") -> 11 | C103: Accounts with ≥ £100 potential recapture | D103: Calculated | H103: HomeCart Online 03 | I103: =O9 -> 256.08718
A104: Accounts Above Policy | B104: =COUNTIF(L6:L95,">0") -> 57 | C104: Accounts with excess discount > 0 | D104: Calculated | H104: Direct Family Customer 02 | I104: =O10 -> 212.70422
H105: WellSpring Pharmacy 03 | I105: =O11 -> 173.37141
H106: LittleNest Retail 02 | I106: =O12 -> 163.95908
H107: HomeCart Online 02 | I107: =O13 -> 144.53471
H108: FamilyCare Wholesale 02 | I108: =O14 -> 127.50924
H109: Direct Family Customer 03 | I109: =O15 -> 115.14717

Sheet Customer Matrix
A1: Customer Profitability Matrix
A3: Segmentation uses median revenue and median contribution margin from the synthetic customer portfolio.
A5: Quadrant thresholds
A6: Metric | B6: Threshold
A7: Median Customer Revenue | B7: =MEDIAN(E12:E101) -> 5571.1864
A8: Median Contribution Margin | B8: =MEDIAN(G12:G101) -> 0.37451585
A11: Customer ID | B11: Customer Name | C11: Channel | D11: Tier | E11: Net Revenue (£) | F11: Contribution Profit (£) | G11: Contribution Margin | H11: Discount Rate | I11: Revenue vs Median | J11: Margin vs Median | K11: Quadrant | L11: Recommended Focus
A12: C046 | B12: Direct Family Customer 01 | C12: DTC | D12: Strategic | E12: 29695.553 | F12: 11810.533 | G12: 0.39772061 | H12: 0.074005425 | I12: =IF(E12>=$B$7,"High","Low") -> High | J12: =IF(G12>=$B$8,"High","Low") -> High | K12: =IF(AND(I12="High",J12="High"),"Protect / Grow",IF(AND(I12="High",J12="Low"),"Reprice / Cost-to-Serve",IF(AND(I12="Low",J12="High"),"Develop / Grow","Review / Deprioritise"))) -> Protect / Grow | L12: =IF(K12="Protect / Grow","Defend relationship and expand profitable volume",IF(K12="Reprice / Cost-to-Serve","Review discounts, freight and service economics",IF(K12="Develop / Grow","Target selective volume growth","Review account economics and strategic fit"))) -> Defend relationship and expand profitable volume
A13: C047 | B13: Direct Family Customer 02 | C13: DTC | D13: Strategic | E13: 28448.002 | F13: 10752.882 | G13: 0.37798374 | H13: 0.081698949 | I13: =IF(E13>=$B$7,"High","Low") -> High | J13: =IF(G13>=$B$8,"High","Low") -> High | K13: =IF(AND(I13="High",J13="High"),"Protect / Grow",IF(AND(I13="High",J13="Low"),"Reprice / Cost-to-Serve",IF(AND(I13="Low",J13="High"),"Develop / Grow","Review / Deprioritise"))) -> Protect / Grow | L13: =IF(K13="Protect / Grow","Defend relationship and expand profitable volume",IF(K13="Reprice / Cost-to-Serve","Review discounts, freight and service economics",IF(K13="Develop / Grow","Target selective volume growth","Review account economics and strategic fit"))) -> Defend relationship and expand profitable volume
A14: C077 | B14: LittleNest Retail 02 | C14: Baby Specialist | D14: Strategic | E14: 23824.362 | F14: 8796.2518 | G14: 0.36921248 | H14: 0.12358106 | I14: =IF(E14>=$B$7,"High","Low") -> High | J14: =IF(G14>=$B$8,"High","Low") -> Low | K14: =IF(AND(I14="High",J14="High"),"Protect / Grow",IF(AND(I14="High",J14="Low"),"Reprice / Cost-to-Serve",IF(AND(I14="Low",J14="High"),"Develop / Grow","Review / Deprioritise"))) -> Reprice / Cost-to-Serve | L14: =IF(K14="Protect / Grow","Defend relationship and expand profitable volume",IF(K14="Reprice / Cost-to-Serve","Review discounts, freight and service economics",IF(K14="Develop / Grow","Target selective volume growth","Review account economics and strategic fit"))) -> Review discounts, freight and service economics
A15: C001 | B15: Northgate Grocers 01 | C15: Grocery | D15: Strategic | E15: 23314.544 | F15: 8233.2724 | G15: 0.3531389 | H15: 0.16467481 | I15: =IF(E15>=$B$7,"High","Low") -> High | J15: =IF(G15>=$B$8,"High","Low") -> Low | K15: =IF(AND(I15="High",J15="High"),"Protect / Grow",IF(AND(I15="High",J15="Low"),"Reprice / Cost-to-Serve",IF(AND(I15="Low",J15="High"),"Develop / Grow","Review / Deprioritise"))) -> Reprice / Cost-to-Serve | L15: =IF(K15="Protect / Grow","Defend relationship and expand profitable volume",IF(K15="Reprice / Cost-to-Serve","Review discounts, freight and service economics",IF(K15="Develop / Grow","Target selective volume growth","Review account economics and strategic fit"))) -> Review discounts, freight and service economics
A16: C031 | B16: HomeCart Online 01 | C16: Online Marketplace | D16: Strategic | E16: 21393.976 | F16: 7298.4322 | G16: 0.34114427 | H16: 0.17332026 | I16: =IF(E16>=$B$7,"High","Low") -> High | J16: =IF(G16>=$B$8,"High","Low") -> Low | K16: =IF(AND(I16="High",J16="High"),"Protect / Grow",IF(AND(I16="High",J16="Low"),"Reprice / Cost-to-Serve",IF(AND(I16="Low",J16="High"),"Develop / Grow","Review / Deprioritise"))) -> Reprice / Cost-to-Serve | L16: =IF(K16="Protect / Grow","Defend relationship and expand profitable volume",IF(K16="Reprice / Cost-to-Serve","Review discounts, freight and service economics",IF(K16="Develop / Grow","Target selective volume growth","Review account economics and strategic fit"))) -> Review discounts, freight and service economics
A17: C033 | B17: HomeCart Online 03 | C17: Online Marketplace | D17: Strategic | E17: 21060.262 | F17: 6649.9756 | G17: 0.31575939 | H17: 0.179612 | I17: =IF(E17>=$B$7,"High","Low") -> High | J17: =IF(G17>=$B$8,"High","Low") -> Low | K17: =IF(AND(I17="High",J17="High"),"Protect / Grow",IF(AND(I17="High",J17="Low"),"Reprice / Cost-to-Serve",IF(AND(I17="Low",J17="High"),"Develop / Grow","Review / Deprioritise"))) -> Reprice / Cost-to-Serve | L17: =IF(K17="Protect / Grow","Defend relationship and expand profitable volume",IF(K17="Reprice / Cost-to-Serve","Review discounts, freight and service economics",IF(K17="Develop / Grow","Target selective volume growth","Review account economics and strategic fit"))) -> Review discounts, freight and service economics
A18: C048 | B18: Direct Family Customer 03 | C18: DTC | D18: Strategic | E18: 20694.212 | F18: 8075.2223 | G18: 0.39021647 | H18: 0.083759327 | I18: =IF(E18>=$B$7,"High","Low") -> High | J18: =IF(G18>=$B$8,"High","Low") -> High | K18: =IF(AND(I18="High",J18="High"),"Protect / Grow",IF(AND(I18="High",J18="Low"),"Reprice / Cost-to-Serve",IF(AND(I18="Low",J18="High"),"Develop / Grow","Review / Deprioritise"))) -> Protect / Grow | L18: =IF(K18="Protect / Grow","Defend relationship and expand profitable volume",IF(K18="Reprice / Cost-to-Serve","Review discounts, freight and service economics",IF(K18="Develop / Grow","Target selective volume growth","Review account economics and strategic fit"))) -> Defend relationship and expand profitable volume
A19: C032 | B19: HomeCart Online 02 | C19: Online Marketplace | D19: Strategic | E19: 20627.807 | F19: 6834.6545 | G19: 0.33133209 | H19: 0.17193183 | I19: =IF(E19>=$B$7,"High","Low") -> High | J19: =IF(G19>=$B$8,"High","Low") -> Low | K19: =IF(AND(I19="High",J19="High"),"Protect / Grow",IF(AND(I19="High",J19="Low"),"Reprice / Cost-to-Serve",IF(AND(I19="Low",J19="High"),"Develop / Grow","Review / Deprioritise"))) -> Reprice / Cost-to-Serve | L19: =IF(K19="Protect / Grow","Defend relationship and expand profitable volume",IF(K19="Reprice / Cost-to-Serve","Review discounts, freight and service economics",IF(K19="Develop / Grow","Target selective volume growth","Review account economics and strategic fit"))) -> Review discounts, freight and service economics
A20: C018 | B20: WellSpring Pharmacy 03 | C20: Pharmacy | D20: Strategic | E20: 20045.679 | F20: 7666.1395 | G20: 0.38243352 | H20: 0.13566147 | I20: =IF(E20>=$B$7,"High","Low") -> High | J20: =IF(G20>=$B$8,"High","Low") -> High | K20: =IF(AND(I20="High",J20="High"),"Protect / Grow",IF(AND(I20="High",J20="Low"),"Reprice / Cost-to-Serve",IF(AND(I20="Low",J20="High"),"Develop / Grow","Review / Deprioritise"))) -> Protect / Grow | L20: =IF(K20="Protect / Grow","Defend relationship and expand profitable volume",IF(K20="Reprice / Cost-to-Serve","Review discounts, freight and service economics",IF(K20="Develop / Grow","Target selective volume growth","Review account economics and strategic fit"))) -> Defend relationship and expand profitable volume
A21: C078 | B21: LittleNest Retail 03 | C21: Baby Specialist | D21: Strategic | E21: 19839.5 | F21: 7453.0119 | G21: 0.3756653 | H21: 0.11530764 | I21: =IF(E21>=$B$7,"High","Low") -> High | J21: =IF(G21>=$B$8,"High","Low") -> High | K21: =IF(AND(I21="High",J21="High"),"Protect / Grow",IF(AND(I21="High",J21="Low"),"Reprice / Cost-to-Serve",IF(AND(I21="Low",J21="High"),"Develop / Grow","Review / Deprioritise"))) -> Protect / Grow | L21: =IF(K21="Protect / Grow","Defend relationship and expand profitable volume",IF(K21="Reprice / Cost-to-Serve","Review discounts, freight and service economics",IF(K21="Develop / Grow","Target selective volume growth","Review account economics and strategic fit"))) -> Defend relationship and expand profitable volume
A22: C017 | B22: WellSpring Pharmacy 02 | C22: Pharmacy | D22: Strategic | E22: 19566.794 | F22: 7153.0515 | G22: 0.36557095 | H22: 0.12629869 | I22: =IF(E22>=$B$7,"High","Low") -> High | J22: =IF(G22>=$B$8,"High","Low") -> Low | K22: =IF(AND(I22="High",J22="High"),"Protect / Grow",IF(AND(I22="High",J22="Low"),"Reprice / Cost-to-Serve",IF(AND(I22="Low",J22="High"),"Develop / Grow","Review / Deprioritise"))) -> Reprice / Cost-to-Serve | L22: =IF(K22="Protect / Grow","Defend relationship and expand profitable volume",IF(K22="Reprice / Cost-to-Serve","Review discounts, freight and service economics",IF(K22="Develop / Grow","Target selective volume growth","Review account economics and strategic fit"))) -> Review discounts, freight and service economics
A23: C063 | B23: FamilyCare Wholesale 03 | C23: Wholesale | D23: Strategic | E23: 17977.78 | F23: 5949.2536 | G23: 0.33092259 | H23: 0.1993856 | I23: =IF(E23>=$B$7,"High","Low") -> High | J23: =IF(G23>=$B$8,"High","Low") -> Low | K23: =IF(AND(I23="High",J23="High"),"Protect / Grow",IF(AND(I23="High",J23="Low"),"Reprice / Cost-to-Serve",IF(AND(I23="Low",J23="High"),"Develop / Grow","Review / Deprioritise"))) -> Reprice / Cost-to-Serve | L23: =IF(K23="Protect / Grow","Defend relationship and expand profitable volume",IF(K23="Reprice / Cost-to-Serve","Review discounts, freight and service economics",IF(K23="Develop / Grow","Target selective volume growth","Review account economics and strategic fit"))) -> Review discounts, freight and service economics
... A101: C059 | B101: Direct Family Customer 14 | C101: DTC | D101: Long Tail | E101: 377.34381 | F101: 152.04334 | G101: 0.40293053 | H101: 0.063477082 | I101: =IF(E101>=$B$7,"High","Low") -> Low | J101: =IF(G101>=$B$8,"High","Low") -> High | K101: =IF(AND(I101="High",J101="High"),"Protect / Grow",IF(AND(I101="High",J101="Low"),"Reprice / Cost-to-Serve",IF(AND(I101="Low",J101="High"),"Develop / Grow","Review / Deprioritise"))) -> Develop / Grow | L101: =IF(K101="Protect / Grow","Defend relationship and expand profitable volume",IF(K101="Reprice / Cost-to-Serve","Review discounts, freight and service economics",IF(K101="Develop / Grow","Target selective volume growth","Review account economics and strategic fit"))) -> Target selective volume growth
A104: Quadrant summary
A105: Quadrant | B105: Customers | C105: Net Revenue (£) | D105: Contribution Profit (£)
A106: Protect / Grow | B106: =COUNTIF(K12:K101,A106) -> 21 | C106: =SUMIF(K12:K101,A106,E12:E101) -> 255252.25 | D106: =SUMIF(K12:K101,A106,F12:F101) -> 99169.457
A107: Reprice / Cost-to-Serve | B107: =COUNTIF(K12:K101,A107) -> 24 | C107: =SUMIF(K12:K101,A107,E12:E101) -> 298666.01 | D107: =SUMIF(K12:K101,A107,F12:F101) -> 103208.36
A108: Develop / Grow | B108: =COUNTIF(K12:K101,A108) -> 24 | C108: =SUMIF(K12:K101,A108,E12:E101) -> 35169.486 | D108: =SUMIF(K12:K101,A108,F12:F101) -> 13688.159
A109: Review / Deprioritise | B109: =COUNTIF(K12:K101,A109) -> 21 | C109: =SUMIF(K12:K101,A109,E12:E101) -> 43693.72 | D109: =SUMIF(K12:K101,A109,F12:F101) -> 14997.823

Sheet Pricing Waterfall
A1: Pricing & Margin Waterfall
A3: Commercial bridge from list-price gross sales to contribution profit. All figures are synthetic.
A5: Portfolio pricing waterfall
A6: Step | B6: Impact (£) | C6: Running Value (£) | E6: KPI | F6: Value
A7: Gross Sales | B7: 730829.56 | C7: 730829.56 | E7: Discount Rate | F7: 0.13415999
A8: Discounts | B8: -98048.089 | C8: 632781.47 | E8: Gross Margin | F8: 0.39434954
A9: Net Revenue | B9: 0 | C9: 632781.47 | E9: Contribution Margin | F9: 0.36515577
A10: COGS | B10: -383244.39 | C10: 249537.08 | E10: Cost-to-Serve % | F10: 0.029193772
A11: Gross Profit | B11: 0 | C11: 249537.08
A12: Freight | B12: -16258.148 | C12: 233278.93
A13: Promo Spend | B13: -2215.13 | C13: 231063.8
A14: Contribution Profit | B14: 0 | C14: 231063.8
A17: Waterfall by channel
A18: Channel | B18: Gross Sales (£) | C18: Discounts (£) | D18: Net Revenue (£) | E18: COGS (£) | F18: Gross Profit (£) | G18: Freight (£) | H18: Promo Spend (£) | I18: Contribution Profit (£) | J18: Contribution Margin
A19: DTC | B19: 138529.4 | C19: 10161.515 | D19: 128367.88 | E19: 72088.76 | F19: 56279.125 | G19: 5776.5548 | H19: 342.25 | I19: 50160.32 | J19: 0.39075443
A20: Baby Specialist | B20: 120644.91 | C20: 13422.029 | D20: 107222.88 | E20: 64006.94 | F20: 43215.941 | G20: 2466.1263 | H20: 322.29 | I20: 40427.525 | J20: 0.37704196
A21: Pharmacy | B21: 120588.67 | C21: 14666.024 | D21: 105922.65 | E21: 63056.27 | F21: 42866.376 | G21: 2224.3756 | H21: 274.8 | I21: 40367.201 | J21: 0.38110076
A22: Online Marketplace | B22: 126233.66 | C22: 21202.021 | D22: 105031.64 | E22: 66263.39 | F22: 38768.249 | G22: 2730.8226 | H22: 625.63 | I22: 35411.797 | J22: 0.33715361
A23: Wholesale | B23: 120203.06 | C23: 22874.096 | D23: 97328.964 | E23: 62803.15 | F23: 34525.814 | G23: 1459.9345 | H23: 247.65 | I23: 32818.23 | J23: 0.33718873
A24: Grocery | B24: 104629.86 | C24: 15722.405 | D24: 88907.455 | E24: 55025.88 | F24: 33881.575 | G24: 1600.3342 | H24: 402.51 | I24: 31878.731 | J24: 0.35856083

Sheet Promo Effectiveness
A1: Promotion Effectiveness & ROI Proxy
A3: ROI is an observational effectiveness proxy: actual promo contribution is compared with a non-promo transaction baseline. It is not a causal experiment.
A6: Category | B6: Promo Txns | C6: Non-Promo Txns | D6: Promo Units / Txn | E6: Non-Promo Units / Txn | F6: Unit Uplift % | G6: Promo Revenue (£) | H6: Promo Spend (£) | I6: Promo CM | J6: Non-Promo CM | K6: Incremental Contribution Proxy (£) | L6: ROI Proxy | M6: Assessment | O6: Category | P6: ROI Proxy
A7: Skincare | B7: 51 | C7: 227 | D7: 30.627451 | E7: 28.365639 | F7: 0.07973775 | G7: 11681.458 | H7: 221.48 | I7: 0.40395131 | J7: 0.43740949 | K7: 249.27851 | L7: 1.1255125 | M7: =IF(L7>=1,"Strong",IF(L7>0,"Marginal","Value destructive")) -> Strong | O7: Skincare | P7: 1.1255125
A8: Baby Bath | B8: 64 | C8: 275 | D8: 39.953125 | E8: 33.214545 | F8: 0.20288038 | G8: 13524.281 | H8: 296.88 | I8: 0.38568268 | J8: 0.432616 | K8: 237.25537 | L8: 0.79916251 | M8: =IF(L8>=1,"Strong",IF(L8>0,"Marginal","Value destructive")) -> Marginal | O8: Baby Bath | P8: 0.79916251
A9: Wipes | B9: 90 | C9: 386 | D9: 54.7 | E9: 51.774611 | F9: 0.056502377 | G9: 28377.894 | H9: 591.85 | I9: 0.32136176 | J9: 0.37167401 | K9: -872.20449 | L9: -1.4736918 | M9: =IF(L9>=1,"Strong",IF(L9>0,"Marginal","Value destructive")) -> Value destructive | O9: Wipes | P9: -1.4736918
A10: Feeding | B10: 36 | C10: 216 | D10: 26.111111 | E10: 23.574074 | F10: 0.1076198 | G10: 6256.1351 | H10: 121.25 | I10: 0.33118901 | J10: 0.39234774 | K10: -298.54171 | L10: -2.4621997 | M10: =IF(L10>=1,"Strong",IF(L10>0,"Marginal","Value destructive")) -> Value destructive | O10: Feeding | P10: -2.4621997
A11: Diapers | B11: 91 | C11: 425 | D11: 50.373626 | E11: 50.6 | F11: -0.0044737871 | G11: 47070.854 | H11: 927.61 | I11: 0.28825156 | J11: 0.35253271 | K11: -5400.6589 | L11: -5.8221224 | M11: =IF(L11>=1,"Strong",IF(L11>0,"Marginal","Value destructive")) -> Value destructive | O11: Diapers | P11: -5.8221224
